<?xml version="1.0"?>
<robot name="panda">
  <!-- Base Link -->
  <link name="panda_link0">
    <visual>
      <geometry>
        <cylinder length="0.12" radius="0.06"/>
      </geometry>
      <material name="white">
        <color rgba="1.0 1.0 1.0 1.0"/>
      </material>
    </visual>
    <collision>
      <geometry>
        <cylinder length="0.12" radius="0.06"/>
      </geometry>
    </collision>
    <inertial>
      <mass value="3.0"/>
      <inertia ixx="0.0108" ixy="0" ixz="0" iyy="0.0108" iyz="0" izz="0.0054"/>
    </inertial>
  </link>

  <!-- Joint 1 -->
  <joint name="panda_joint1" type="revolute">
    <parent link="panda_link0"/>
    <child link="panda_link1"/>
    <origin xyz="0 0 0.333" rpy="0 0 0"/>
    <axis xyz="0 0 1"/>
    <limit lower="-2.8973" upper="2.8973" effort="87" velocity="2.175"/>
  </joint>

  <link name="panda_link1">
    <visual>
      <geometry>
        <cylinder length="0.12" radius="0.06"/>
      </geometry>
      <material name="white"/>
    </visual>
    <collision>
      <geometry>
        <cylinder length="0.12" radius="0.06"/>
      </geometry>
    </collision>
    <inertial>
      <mass value="4.970684"/>
      <origin xyz="0.003875 0.002081 -0.04762"/>
      <inertia ixx="0.70337" ixy="-0.000139" ixz="0.006772" iyy="0.70661" iyz="0.019169" izz="0.009117"/>
    </inertial>
  </link>

  <!-- Joint 2 -->
  <joint name="panda_joint2" type="revolute">
    <parent link="panda_link1"/>
    <child link="panda_link2"/>
    <origin xyz="0 0 0" rpy="-1.5708 0 0"/>
    <axis xyz="0 0 1"/>
    <limit lower="-1.7628" upper="1.7628" effort="87" velocity="2.175"/>
  </joint>

  <link name="panda_link2">
    <visual>
      <origin xyz="0 0 0" rpy="0 0 0"/>
      <geometry>
        <cylinder length="0.12" radius="0.06"/>
      </geometry>
      <material name="white"/>
    </visual>
    <collision>
      <origin xyz="0 0 0" rpy="0 0 0"/>
      <geometry>
        <cylinder length="0.12" radius="0.06"/>
      </geometry>
    </collision>
    <inertial>
      <mass value="0.646926"/>
      <origin xyz="-0.003141 -0.02872 0.003495"/>
      <inertia ixx="0.007962" ixy="-0.003925" ixz="0.010254" iyy="0.02811" iyz="0.000704" izz="0.025995"/>
    </inertial>
  </link>

  <!-- Joint 3 -->
  <joint name="panda_joint3" type="revolute">
    <parent link="panda_link2"/>
    <child link="panda_link3"/>
    <origin xyz="0 -0.316 0" rpy="1.5708 0 0"/>
    <axis xyz="0 0 1"/>
    <limit lower="-2.8973" upper="2.8973" effort="87" velocity="2.175"/>
  </joint>

  <link name="panda_link3">
    <visual>
      <geometry>
        <cylinder length="0.12" radius="0.06"/>
      </geometry>
      <material name="white"/>
    </visual>
    <collision>
      <geometry>
        <cylinder length="0.12" radius="0.06"/>
      </geometry>
    </collision>
    <inertial>
      <mass value="3.228604"/>
      <origin xyz="0.02796 0.041065 -0.02522"/>
      <inertia ixx="0.037242" ixy="-0.004761" ixz="-0.011396" iyy="0.036155" iyz="-0.012805" izz="0.01083"/>
    </inertial>
  </link>

  <!-- Joint 4 -->
  <joint name="panda_joint4" type="revolute">
    <parent link="panda_link3"/>
    <child link="panda_link4"/>
    <origin xyz="0.0825 0 0" rpy="1.5708 0 0"/>
    <axis xyz="0 0 1"/>
    <limit lower="-3.0718" upper="-0.0698" effort="87" velocity="2.175"/>
  </joint>

  <link name="panda_link4">
    <visual>
      <geometry>
        <cylinder length="0.12" radius="0.06"/>
      </geometry>
      <material name="white"/>
    </visual>
    <collision>
      <geometry>
        <cylinder length="0.12" radius="0.06"/>
      </geometry>
    </collision>
    <inertial>
      <mass value="3.587895"/>
      <origin xyz="-0.05317 0.104419 0.02739"/>
      <inertia ixx="0.025853" ixy="0.007796" ixz="-0.001332" iyy="0.019552" iyz="0.008641" izz="0.028323"/>
    </inertial>
  </link>

  <!-- Joint 5 -->
  <joint name="panda_joint5" type="revolute">
    <parent link="panda_link4"/>
    <child link="panda_link5"/>
    <origin xyz="-0.0825 0.384 0" rpy="-1.5708 0 0"/>
    <axis xyz="0 0 1"/>
    <limit lower="-2.8973" upper="2.8973" effort="12" velocity="2.61"/>
  </joint>

  <link name="panda_link5">
    <visual>
      <geometry>
        <cylinder length="0.12" radius="0.06"/>
      </geometry>
      <material name="white"/>
    </visual>
    <collision>
      <geometry>
        <cylinder length="0.12" radius="0.06"/>
      </geometry>
    </collision>
    <inertial>
      <mass value="1.225946"/>
      <origin xyz="-0.011953 0.041065 -0.038437"/>
      <inertia ixx="0.035549" ixy="-0.002117" ixz="-0.004037" iyy="0.029474" iyz="0.000229" izz="0.008627"/>
    </inertial>
  </link>

  <!-- Joint 6 -->
  <joint name="panda_joint6" type="revolute">
    <parent link="panda_link5"/>
    <child link="panda_link6"/>
    <origin xyz="0 0 0" rpy="1.5708 0 0"/>
    <axis xyz="0 0 1"/>
    <limit lower="-0.0175" upper="3.7525" effort="12" velocity="2.61"/>
  </joint>

  <link name="panda_link6">
    <visual>
      <geometry>
        <cylinder length="0.08" radius="0.05"/>
      </geometry>
      <material name="white"/>
    </visual>
    <collision>
      <geometry>
        <cylinder length="0.08" radius="0.05"/>
      </geometry>
    </collision>
    <inertial>
      <mass value="1.666555"/>
      <origin xyz="0.060149 -0.014117 -0.010517"/>
      <inertia ixx="0.001964" ixy="0.000109" ixz="-0.000341" iyy="0.004354" iyz="0.000291" izz="0.005433"/>
    </inertial>
  </link>

  <!-- Joint 7 -->
  <joint name="panda_joint7" type="revolute">
    <parent link="panda_link6"/>
    <child link="panda_link7"/>
    <origin xyz="0.088 0 0" rpy="1.5708 0 0"/>
    <axis xyz="0 0 1"/>
    <limit lower="-2.8973" upper="2.8973" effort="12" velocity="2.61"/>
  </joint>

  <link name="panda_link7">
    <visual>
      <geometry>
        <cylinder length="0.05" radius="0.04"/>
      </geometry>
      <material name="white"/>
    </visual>
    <collision>
      <geometry>
        <cylinder length="0.05" radius="0.04"/>
      </geometry>
    </collision>
    <inertial>
      <mass value="0.735522"/>
      <origin xyz="0.01 0.01 0.03"/>
      <inertia ixx="0.012" ixy="-0.000002" ixz="0.000004" iyy="0.012" iyz="0.000006" izz="0.004"/>
    </inertial>
  </link>

  <!-- Hand Joint -->
  <joint name="panda_hand_joint" type="fixed">
    <parent link="panda_link7"/>
    <child link="panda_hand"/>
    <origin xyz="0 0 0.107" rpy="0 0 -0.7854"/>
  </joint>

  <link name="panda_hand">
    <visual>
      <geometry>
        <box size="0.08 0.12 0.04"/>
      </geometry>
      <material name="grey">
        <color rgba="0.5 0.5 0.5 1.0"/>
      </material>
    </visual>
    <collision>
      <geometry>
        <box size="0.08 0.12 0.04"/>
      </geometry>
    </collision>
    <inertial>
      <mass value="0.73"/>
      <origin xyz="0 0 0.02"/>
      <inertia ixx="0.001" ixy="0" ixz="0" iyy="0.0025" iyz="0" izz="0.0017"/>
    </inertial>
  </link>

  <!-- Left Finger -->
  <joint name="panda_finger_joint1" type="prismatic">
    <parent link="panda_hand"/>
    <child link="panda_leftfinger"/>
    <origin xyz="0 0 0.0584" rpy="0 0 0"/>
    <axis xyz="0 1 0"/>
    <limit lower="0.0" upper="0.04" effort="20" velocity="0.2"/>
  </joint>

  <link name="panda_leftfinger">
    <visual>
      <geometry>
        <box size="0.01 0.01 0.05"/>
      </geometry>
      <material name="grey"/>
    </visual>
    <collision>
      <geometry>
        <box size="0.01 0.01 0.05"/>
      </geometry>
    </collision>
    <inertial>
      <mass value="0.01"/>
      <inertia ixx="0.00001" ixy="0" ixz="0" iyy="0.00001" iyz="0" izz="0.00001"/>
    </inertial>
  </link>

  <!-- Right Finger -->
  <joint name="panda_finger_joint2" type="prismatic">
    <parent link="panda_hand"/>
    <child link="panda_rightfinger"/>
    <origin xyz="0 0 0.0584" rpy="0 0 0"/>
    <axis xyz="0 -1 0"/>
    <limit lower="0.0" upper="0.04" effort="20" velocity="0.2"/>
  </joint>

  <link name="panda_rightfinger">
    <visual>
      <geometry>
        <box size="0.01 0.01 0.05"/>
      </geometry>
      <material name="grey"/>
    </visual>
    <collision>
      <geometry>
        <box size="0.01 0.01 0.05"/>
      </geometry>
    </collision>
    <inertial>
      <mass value="0.01"/>
      <inertia ixx="0.00001" ixy="0" ixz="0" iyy="0.00001" iyz="0" izz="0.00001"/>
    </inertial>
  </link>

</robot>
